Workbook

Sheet Manifest
A6: MANIFEST CARGO
A7: MYI-KAL/100718/XII/2025 | H7: STOWING CHEKLIST
B8: DATE | C8: : 02/03/2026 | F8: A/C REG | G8: : | H8: DATE | I8: =C8 -> : 02/03/2026 | L8: A/C REG | M8: =G8 -> :
B9: FROM | C9: : DJJ | F9: FLIGHT NO | G9: : TRIMG | H9: FROM | I9: : DJJ | L9: FLIGHT NO | M9: =G9 -> : TRIMG
B10: TO | C10: : WMX | F10: FLT FREQ | G10: : | H10: TO | I10: : WMX | L10: FLT FREQ | M10: =G10 -> :
A12: No | B12: PTI | C12: Pcs/ Cly | D12: WEIGHT (Kg) | F12: DESCRIPTION | G12: COSTUMERS | H12: No | I12: NO PAG | J12: DESCRIPTION | K12: WEIGHT (Kg) | M12: COSTUMERS
D13: Pcs/ Cly | E13: Sub Total | K13: Net | L13: Gross
A14: 1 | H14: 1 | L14: =K14+125 -> 125
A15: 2 | H15: 2 | L15: =K15+125 -> 125
A16: 3 | H16: 3 | L16: =K16+125 -> 125
A17: 4 | H17: 4 | L17: =K17+125 -> 125
A18: 5 | H18: 5 | L18: =K18+125 -> 125
A19: 6 | H19: 6 | L19: =K19+125 -> 125
A20: 7 | H20: 7 | L20: =K20+125 -> 125
A21: 8 | H21: 8 | L21: =K21+125 -> 125
A22: 9 | H22: 9 | L22: =K22+125 -> 125
A23: 10 | H23: 10 | L23: =K23+125 -> 125
A24: 11 | H24: 11 | L24: =K24+125 -> 125
A25: 12 | H25: 12 | L25: =K25+125 -> 125
... A28: 15 | H28: 15 | L28: =K28+125 -> 125
A29: 16 | H29: 16
A30: 17 | H30: 17
A31: 18 | H31: 18
A32: 19 | H32: 19
A33: 20 | H33: 20
A34: 21 | H34: MANUAL LOAD
A35: 22
A36: 23
A37: 24 | H37: TOTAL WEIGHT | K37: =SUM(K14:K36) -> - | L37: =SUM(L14:L36) -> 1,875
A38: 25
A39: 26
A40: 27 | J40: Prepared by : | L40: Approved by :
A41: 28
A42: 29
A43: 30 | J43: M NUR ALAM | L43: FOO INCHARGE
A44: 31
A45: TOTAL WEIGHT | C45: =SUM(C14:C44) -> - | D45: =SUM(D14:D44) -> - | E45: =SUM(E14:E44) -> -
A48: Prepared by : | F48: Approved by Acceptance:
A52: M NUR ALAM
O123: 3150 | P123: Budi Jaya
...

Sheet DATA CUSTOMER 
A6: MANIFEST CARGO
A7: MYI-KAL/100718/XII/2025 | H7: STOWING CHEKLIST
B8: DATE | C8: : 02/03/2026 | F8: A/C REG | G8: : | H8: DATE | I8: =C8 -> : 02/03/2026 | L8: A/C REG | M8: =G8 -> :
B9: FROM | C9: : DJJ | F9: FLIGHT NO | G9: : TRIMG | H9: FROM | I9: : DJJ | L9: FLIGHT NO | M9: =G9 -> : TRIMG
B10: TO | C10: : WMX | F10: FLT FREQ | G10: : | H10: TO | I10: : WMX | L10: FLT FREQ | M10: =G10 -> :
A12: No | B12: PTI | C12: Pcs/ Cly | D12: WEIGHT (Kg) | F12: DESCRIPTION | G12: COSTUMERS | H12: No | I12: NO PAG | J12: DESCRIPTION | K12: WEIGHT (Kg) | M12: COSTUMERS
D13: Pcs/ Cly | E13: Sub Total | K13: Net | L13: Gross
A14: 1 | H14: 1 | L14: =K14+125 -> 125
A15: 2 | H15: 2 | L15: =K15+125 -> 125
A16: 3 | H16: 3 | L16: =K16+125 -> 125
A17: 4 | H17: 4 | L17: =K17+125 -> 125
A18: 5 | H18: 5 | L18: =K18+125 -> 125
A19: 6 | H19: 6 | L19: =K19+125 -> 125
A20: 7 | H20: 7 | L20: =K20+125 -> 125
A21: 8 | H21: 8 | L21: =K21+125 -> 125
A22: 9 | H22: 9 | L22: =K22+125 -> 125
A23: 10 | H23: 10 | L23: =K23+125 -> 125
A24: 11 | H24: 11 | L24: =K24+125 -> 125
A25: 12 | H25: 12 | L25: =K25+125 -> 125
... A28: 15 | H28: 15 | L28: =K28+125 -> 125
A29: 16 | H29: 16
A30: 17 | H30: 17
A31: 18 | H31: 18
A32: 19 | H32: 19
A33: 20 | H33: 20
A34: 21 | H34: MANUAL LOAD
A35: 22
A36: 23
A37: 24 | H37: TOTAL WEIGHT | K37: =SUM(K14:K36) -> - | L37: =SUM(L14:L36) -> 1,875
A38: 25
A39: 26
A40: 27 | J40: Prepared by : | L40: Approved by :
A41: 28
A42: 29
A43: 30 | J43: M NUR ALAM | L43: FOO INCHARGE
A44: 31
A45: TOTAL WEIGHT | C45: =SUM(C14:C44) -> - | D45: =SUM(D14:D44) -> - | E45: =SUM(E14:E44) -> -
A48: Prepared by : | F48: Approved by Acceptance:
A52: M NUR ALAM
O123: 3150 | P123: Budi Jaya
...

Sheet Sheet1
A1: 1 | E1: =C1*D1 -> 0
E2: =C2*D2 -> 0
A3: 2 | E3: =C3*D3 -> 0
A4: 3 | E4: =C4*D4 -> 0
A5: 4 | E5: =C5*D5 -> 0
A6: 5 | E6: =C6*D6 -> 0
A7: 6 | E7: =C7*D7 -> 0
A8: 7 | E8: =C8*D8 -> 0
A9: 8 | E9: =C9*D9 -> 0
A10: 9 | E10: =C10*D10 -> 0
A11: 10 | E11: =C11*D11 -> 0
A12: 11 | E12: =C12*D12 -> 0
A13: 12 | E13: =C13*D13 -> 0
A14: 13 | E14: =C14*D14 -> 0
... A43: 42 | E43: =C43*D43 -> 0

Sheet Sheet2
B1: DATE | C1: =Manifest!C8 -> : 02/03/2026 | E1: A/C REG | F1: =Manifest!G8 -> :
B2: FROM | C2: : DJJ | E2: FLIGHT NO | F2: =Manifest!G9 -> : TRIMG
B3: TO | C3: : WMX | E3: FLT FREQ | F3: =Manifest!G10 -> :
A5: No | B5: PTI | C5: PENGIRIM | D5: PENERIMA | E5: JENIS BARANG | F5: KOLI | G5: KG
A7: 1
A8: 2
A9: 3
A10: 4
A11: 5
A12: 6
A13: 7
A14: 8
A15: 9
A16: 10
A17: 11
A18: 12
... A21: 15
F22: =SUM(F7:F21) -> 0

Sheet FFM MYI
A1: KAL
A2: Tanggal | B2: FN | C2: Dest | D2: AWB Number | E2: Total Pcs | F2: Total Weight | G2: Commodity
A3: 46001 | B3: 2Y704 | C3: WMX | D3: =Manifest!G3 | E3: =Manifest!C45 -> - | F3: =Manifest!E45 -> - | G3: CONSOLIDATE
